Traceback (most recent call last):
  File "/home/wangxiangwei/Program/DataMaker/data_maker.py", line 55, in <module>
    motion_output_name = sys.argv[3]
IndexError: list index out of range
Traceback (most recent call last):
  File "/home/wangxiangwei/Program/DataMaker/data_maker.py", line 55, in <module>
    motion_output_name = sys.argv[3]
IndexError: list index out of range
